# :pencil:async와 await 구문

## :speech_balloon:1-1 await 키워드

- awiat 키워드는 피연산자(operand) 의 값을 반환해준다.
- 만일 Promise 객체이면 then 메서드를 호출해 얻은 값을 반환한다.

```typescript
...
let value = await Promise 객체 혹은 값
...
```

## :speech_balloon:1-2 async 함수 수정자

- await 키워드는 asnyc 가 있는 함수 몸통에서만 사용할 수 있다.

```typescript
cosnt arrow = async() => {
    await Promise 객체 혹은 값
}

const function f() {
    await Promise 객체 혹은 값
}
```

## :speech_balloon:1-3 async 함수 특징

- 반환 값이 Promose 형태로 반환된다.
- 따라서 then 메서드를 활용해 async 함수의 반환값을 얻어야 한다.

```typescript
const asyncReturn = async () => {
  return [1, 2, 3]
}

asyncReturn().then((res) => console.log(res)) // [1, 2, 3]
```

## :speech_balloon:1-4 async 함수 예외 처리

- async함수에서 예외가 발생하면 프로그램이 비정상적으로 종료된다.
- 따라서 asyncException()가 반환하는 프로미스 객체의 catch 메서드를 호출하는 형태로 코드를 작성해야 한다.

```typescript
const asyncException = async () => {
  throw new Error("예외가 발생했어여")
}
asyncException() 
  .catch(err => console.log(err.message)) // 예외가 발생했어여
```

- 만일, await 구문에서 Promise.reject 값이 발생해도 비정상적으로 종료된다. 위와 마찬가지로 catch 메서드를 호출하는 형식으로 작성해야 된다.

```typescript
const awaitReject = async () => {
  await Promise.reject(new Error('에러가 발생했어여'))
}

awaitReject().catch((err) => console.log(err.message)) // 에러가 발생했어여
```

